I'm sorry, but an uncaught exception occurred.

While running game code:
  File "game/chapter1/meeting.rpy", line 395, in script
    show gg happy 1
Exception: Image 'gg happy' does not accept attributes '1'.

-- Full Traceback ------------------------------------------------------------

Full traceback:
  File "game/chapter1/meeting.rpy", line 395, in script
    show gg happy 1
  File "/Users/apogodaeva/Documents/renpy-8.3.4-sdk/renpy/ast.py", line 1124, in execute
    show_imspec(self.imspec, atl=getattr(self, "atl", None))
  File "/Users/apogodaeva/Documents/renpy-8.3.4-sdk/renpy/ast.py", line 1087, in show_imspec
    renpy.config.show(name,
  File "/Users/apogodaeva/Documents/renpy-8.3.4-sdk/renpy/exports/displayexports.py", line 477, in show
    if not base.find_target() and renpy.config.missing_show:
  File "/Users/apogodaeva/Documents/renpy-8.3.4-sdk/renpy/display/image.py", line 421, in find_target
    self.target = target._duplicate(a)
  File "/Users/apogodaeva/Documents/renpy-8.3.4-sdk/renpy/display/displayable.py", line 249, in _duplicate
    args.extraneous()
  File "/Users/apogodaeva/Documents/renpy-8.3.4-sdk/renpy/display/displayable.py", line 109, in extraneous
    raise Exception("Image '{}' does not accept attributes '{}'.".format(
Exception: Image 'gg happy' does not accept attributes '1'.

macOS-14.5-arm64-arm-64bit arm64
Ren'Py 8.3.6.25022803
CIRCUS 1.0
Tue Aug  5 19:03:57 2025
